<?xml version="1.0" ?>
<!-- =================================================================================== -->
<!-- |    This document was autogenerated by xacro from proyecto.urdf.xacro            | -->
<!-- |    EDITING THIS FILE BY HAND IS NOT RECOMMENDED                                 | -->
<!-- =================================================================================== -->
<robot name="proyecto">
  <link name="rueda_1">
    <inertial>
      <origin rpy="0 0 0" xyz="-5.707782267661E-07 1.62246123321108E-07 -0.0158002809636204"/>
      <mass value="1.1617081622077"/>
      <inertia ixx="0.00236389228715147" ixy="4.31489359287888E-09" ixz="-1.0352494720813E-08" iyy="0.00236389275249923" iyz="-3.84382849696802E-10" izz="0.00380474886030968"/>
    </inertial>
    <visual>
      <origin rpy="0 0 0" xyz="0 0 0"/>
      <geometry>
        <mesh filename="package://proyecto/meshes/rueda_1.STL"/>
      </geometry>
      <material name="">
        <color rgba="0.792156862745098 0.819607843137255 0.933333333333333 1"/>
      </material>
    </visual>
    <collision>
      <origin rpy="0 0 0" xyz="0 0 0"/>
      <geometry>
        <mesh filename="package://proyecto/meshes/rueda_1.STL"/>
      </geometry>
    </collision>
  </link>
  <joint name="motor_1" type="continuous">
    <origin rpy="1.5707963267948966 0 0" xyz="-0.206 -0.13662 -0.041"/>
    <parent link="base_link"/>
    <child link="rueda_1"/>
    <axis xyz="0 0 1"/>
  </joint>
  <transmission name="tran_1">
    <type>transmission_interface/SimpleTransmission</type>
    <joint name="motor_1">
      <hardwareInterface>hardware_interface/VelocityJointInterface</hardwareInterface>
    </joint>
    <actuator name="motor1">
      <hardwareInterface>hardware_interface/VelocityJointInterface</hardwareInterface>
      <mechanicalReduction>1</mechanicalReduction>
    </actuator>
  </transmission>
  <link name="rueda_2">
    <inertial>
      <origin rpy="0 0 0" xyz="-5.707782267661E-07 1.62246123321108E-07 -0.0158002809636204"/>
      <mass value="1.1617081622077"/>
      <inertia ixx="0.00236389228715147" ixy="4.31489359287888E-09" ixz="-1.0352494720813E-08" iyy="0.00236389275249923" iyz="-3.84382849696802E-10" izz="0.00380474886030968"/>
    </inertial>
    <visual>
      <origin rpy="0 0 0" xyz="0 0 0"/>
      <geometry>
        <mesh filename="package://proyecto/meshes/rueda_2.STL"/>
      </geometry>
      <material name="">
        <color rgba="0.792156862745098 0.819607843137255 0.933333333333333 1"/>
      </material>
    </visual>
    <collision>
      <origin rpy="0 0 0" xyz="0 0 0"/>
      <geometry>
        <mesh filename="package://proyecto/meshes/rueda_2.STL"/>
      </geometry>
    </collision>
  </link>
  <joint name="motor_2" type="continuous">
    <origin rpy="1.5707963267948966 0 0" xyz="-0.206 -0.13662 -0.041"/>
    <parent link="base_link"/>
    <child link="rueda_2"/>
    <axis xyz="0 0 1"/>
  </joint>
  <transmission name="tran_2">
    <type>transmission_interface/SimpleTransmission</type>
    <joint name="motor_2">
      <hardwareInterface>hardware_interface/VelocityJointInterface</hardwareInterface>
    </joint>
    <actuator name="motor2">
      <hardwareInterface>hardware_interface/VelocityJointInterface</hardwareInterface>
      <mechanicalReduction>1</mechanicalReduction>
    </actuator>
  </transmission>
  <link name="rueda_3">
    <inertial>
      <origin rpy="0 0 0" xyz="-5.707782267661E-07 1.62246123321108E-07 -0.0158002809636204"/>
      <mass value="1.1617081622077"/>
      <inertia ixx="0.00236389228715147" ixy="4.31489359287888E-09" ixz="-1.0352494720813E-08" iyy="0.00236389275249923" iyz="-3.84382849696802E-10" izz="0.00380474886030968"/>
    </inertial>
    <visual>
      <origin rpy="0 0 0" xyz="0 0 0"/>
      <geometry>
        <mesh filename="package://proyecto/meshes/rueda_3.STL"/>
      </geometry>
      <material name="">
        <color rgba="0.792156862745098 0.819607843137255 0.933333333333333 1"/>
      </material>
    </visual>
    <collision>
      <origin rpy="0 0 0" xyz="0 0 0"/>
      <geometry>
        <mesh filename="package://proyecto/meshes/rueda_3.STL"/>
      </geometry>
    </collision>
  </link>
  <joint name="motor_3" type="continuous">
    <origin rpy="1.5707963267948966 0 0" xyz="-0.206 -0.13662 -0.041"/>
    <parent link="base_link"/>
    <child link="rueda_3"/>
    <axis xyz="0 0 1"/>
  </joint>
  <transmission name="tran_3">
    <type>transmission_interface/SimpleTransmission</type>
    <joint name="motor_3">
      <hardwareInterface>hardware_interface/VelocityJointInterface</hardwareInterface>
    </joint>
    <actuator name="motor3">
      <hardwareInterface>hardware_interface/VelocityJointInterface</hardwareInterface>
      <mechanicalReduction>1</mechanicalReduction>
    </actuator>
  </transmission>
  <link name="rueda_4">
    <inertial>
      <origin rpy="0 0 0" xyz="-5.707782267661E-07 1.62246123321108E-07 -0.0158002809636204"/>
      <mass value="1.1617081622077"/>
      <inertia ixx="0.00236389228715147" ixy="4.31489359287888E-09" ixz="-1.0352494720813E-08" iyy="0.00236389275249923" iyz="-3.84382849696802E-10" izz="0.00380474886030968"/>
    </inertial>
    <visual>
      <origin rpy="0 0 0" xyz="0 0 0"/>
      <geometry>
        <mesh filename="package://proyecto/meshes/rueda_4.STL"/>
      </geometry>
      <material name="">
        <color rgba="0.792156862745098 0.819607843137255 0.933333333333333 1"/>
      </material>
    </visual>
    <collision>
      <origin rpy="0 0 0" xyz="0 0 0"/>
      <geometry>
        <mesh filename="package://proyecto/meshes/rueda_4.STL"/>
      </geometry>
    </collision>
  </link>
  <joint name="motor_4" type="continuous">
    <origin rpy="1.5707963267948966 0 0" xyz="-0.206 -0.13662 -0.041"/>
    <parent link="base_link"/>
    <child link="rueda_4"/>
    <axis xyz="0 0 1"/>
  </joint>
  <transmission name="tran_4">
    <type>transmission_interface/SimpleTransmission</type>
    <joint name="motor_4">
      <hardwareInterface>hardware_interface/VelocityJointInterface</hardwareInterface>
    </joint>
    <actuator name="motor4">
      <hardwareInterface>hardware_interface/VelocityJointInterface</hardwareInterface>
      <mechanicalReduction>1</mechanicalReduction>
    </actuator>
  </transmission>
  <link name="odom"/>
  <link name="base_link">
    <inertial>
      <origin rpy="0 0 0" xyz="0.0238551640441538 0.0295955080939407 -0.150383488449588"/>
      <mass value="4.58423641056187"/>
      <inertia ixx="0.0171426025781744" ixy="-0.00117297644050985" ixz="-6.44110873168587E-07" iyy="0.0611975209416774" iyz="-1.44180477906026E-08" izz="0.047936942239142"/>
    </inertial>
    <visual>
      <origin rpy="0 0 0" xyz="0 0 0"/>
      <geometry>
        <mesh filename="package://proyecto/meshes/base_link.STL"/>
      </geometry>
      <material name="">
        <color rgba="0.996078431372549 0.996078431372549 1 1"/>
      </material>
    </visual>
    <collision>
      <origin rpy="0 0 0" xyz="0 0 0"/>
      <geometry>
        <mesh filename="package://proyecto/meshes/base_link.STL"/>
      </geometry>
    </collision>
  </link>
  <joint name="dummy_joint" type="fixed">
    <parent link="odom"/>
    <child link="base_link"/>
  </joint>
</robot>

